try{
    let a = 5
    throw new  Error("errro de proposito")
}catch (e) {
    console.log(e)
}